Workbook
Name count: Data_validation!$G$2
Name country: Salary_Dashboard!$J$4:$J$4
Name Median_salary: Jobs!$I$2
Name platform: Platform!$G$2
Name title: Salary_Dashboard!$C$4
Name type: Salary_Dashboard!$P$4

Sheet Data
A1: job_title_short | B1: job_schedule_type | C1: job_country | D1: salary_year_avg | E1: job_via | F1: Column1
A2: Senior Data Scientist | B2: Full-time | C2: Sudan | D2: 128050 | E2: via ZipRecruiter
A3: Data Engineer | B3: Full-time | C3: United States | D3: 140000 | E3: via Indeed
A4: Senior Data Analyst | B4: Full-time | C4: United States | D4: 156000 | E4: via ZipRecruiter
A5: Machine Learning Engineer | B5: Full-time | C5: United States | D5: 140000 | E5: via Ai-Jobs.net
A6: Data Scientist | B6: Full-time and Part-time | C6: United States | E6: via Snagajob
A7: Data Engineer | B7: Full-time and Part-time | C7: Sudan | E7: via Snagajob
A8: Data Engineer | B8: Full-time | C8: United States | D8: 135000 | E8: via Indeed
A9: Senior Data Engineer | B9: Full-time | C9: United States | D9: 120000 | E9: via ZipRecruiter
A10: Senior Data Analyst | B10: Full-time | C10: United States | D10: 170000 | E10: via ZipRecruiter
A11: Data Scientist | B11: Full-time | C11: United States | D11: 224500 | E11: via LinkedIn
A12: Data Scientist | B12: Full-time and Part-time | C12: United States | E12: via Snagajob
A13: Data Scientist | B13: Full-time | C13: United States | D13: 225000 | E13: via Hitmarker
A14: Data Engineer | B14: Full-time and Part-time | C14: United States | E14: via Snagajob
A15: Data Scientist | B15: Full-time | C15: United States | D15: 157500 | E15: via LinkedIn
A16: Data Analyst | B16: Full-time | C16: United States | D16: 149509 | E16: via Indeed
A17: Data Scientist | B17: Contractor | C17: United States | E17: via LinkedIn
A18: Data Engineer | B18: Full-time | C18: United States | D18: 112500 | E18: via LinkedIn
A19: Data Engineer | B19: Full-time | C19: United States | D19: 115000 | E19: via Ladders
A20: Data Scientist | B20: Full-time | C20: United States | D20: 98902 | E20: via Federal Government Jobs
A21: Senior Data Engineer | B21: Full-time and Part-time | C21: United States | D21: 173500 | E21: via SaluteMyJob
A22: Data Analyst | B22: Full-time and Part-time | C22: United States | E22: via JobAffairs4u.com
A23: Data Scientist | B23: Full-time | C23: France | D23: 88128 | E23: via Ai-Jobs.net
A24: Senior Data Scientist | B24: Full-time | C24: United States | D24: 170000 | E24: via LinkedIn
A25: Data Engineer | B25: Contractor | C25: United States | E25: via LinkedIn
A26: Data Scientist | B26: Contractor | C26: United States | D26: 125000 | E26: via LinkedIn
A27: Data Engineer | B27: Full-time | C27: United States | E27: via Snagajob
A28: Senior Data Engineer | B28: Full-time | C28: Sudan | D28: 260775 | E28: via LinkedIn
A29: Senior Data Engineer | B29: Contractor | C29: United States | E29: via LinkedIn
A30: Senior Data Engineer | B30: Full-time | C30: United States | D30: 125000 | E30: via Ladders
A31: Data Scientist | B31: Full-time | C31: United States | E31: via Las Vegas, NV - Geebo
A32: Data Analyst | B32: Full-time | C32: United States | D32: 125000 | E32: via Ladders
A33: Data Scientist | B33: Full-time, Part-time, and Internship | C33: United States | E33: via Snagajob
A34: Data Engineer | B34: Full-time | C34: United States | D34: 97500 | E34: via LinkedIn
A35: Senior Data Engineer | B35: Full-time | C35: United States | D35: 147500 | E35: via Motion Recruitment
A36: Data Analyst | B36: Full-time | C36: United States | D36: 84000 | E36: via Indeed
A37: Data Engineer | B37: Full-time and Part-time | C37: United States | E37: via Snagajob
A38: Data Scientist | B38: Full-time | C38: United States | D38: 105800 | E38: via ZipRecruiter
A39: Data Engineer | B39: Contractor | C39: United States | E39: via LinkedIn
A40: Senior Data Engineer | B40: Full-time | C40: United States | D40: 160000 | E40: via Dice
...

Sheet Jobs
A1: Job_title_short | B1: Median_salary | D1: job_title_short_sorted | E1: Median_salary
A2: {=_xlfn.UNIQUE(Data!A2:A32673)} -> Senior Data Scientist | B2: {=MEDIAN( IF( (jobs[job_title_short]=A2)* (jobs[job_country]=country)* (ISNUMBER(SEARCH(type,jobs[job_schedule_type])))* (Data!$D$2:$D$32673<>0),Data!$D$2:$D$32673 ))} -> #NUM! | D2: {=_xlfn._xlws.SORT(A2:B11,2,1)} -> Senior Data Scientist | E2: #NUM! | F2: =IF($D2<>title,E$2,NA()) -> #NUM! | G2: =IF($D2=title,$E2,NA()) -> #N/A | I2: =_xlfn.XLOOKUP(title,$D$2:$D$11,$E$2:$E$11,"No results") -> #NUM!
A3: Data Engineer | B3: {=MEDIAN( IF( (jobs[job_title_short]=A3)* (jobs[job_country]=country)* (ISNUMBER(SEARCH(type,jobs[job_schedule_type])))* (Data!$D$2:$D$32673<>0),Data!$D$2:$D$32673 ))} -> #NUM! | D3: Data Engineer | E3: #NUM! | F3: =IF($D3<>title,E3,NA()) -> #N/A | G3: =IF($D3=title,$E3,NA()) -> #NUM!
A4: Senior Data Analyst | B4: {=MEDIAN( IF( (jobs[job_title_short]=A4)* (jobs[job_country]=country)* (ISNUMBER(SEARCH(type,jobs[job_schedule_type])))* (Data!$D$2:$D$32673<>0),Data!$D$2:$D$32673 ))} -> #NUM! | D4: Senior Data Analyst | E4: #NUM! | F4: =IF($D4<>title,E4,NA()) -> #NUM! | G4: =IF($D4=title,$E4,NA()) -> #N/A
A5: Machine Learning Engineer | B5: {=MEDIAN( IF( (jobs[job_title_short]=A5)* (jobs[job_country]=country)* (ISNUMBER(SEARCH(type,jobs[job_schedule_type])))* (Data!$D$2:$D$32673<>0),Data!$D$2:$D$32673 ))} -> #NUM! | D5: Machine Learning Engineer | E5: #NUM! | F5: =IF($D5<>title,E5,NA()) -> #NUM! | G5: =IF($D5=title,$E5,NA()) -> #N/A
A6: Data Scientist | B6: {=MEDIAN( IF( (jobs[job_title_short]=A6)* (jobs[job_country]=country)* (ISNUMBER(SEARCH(type,jobs[job_schedule_type])))* (Data!$D$2:$D$32673<>0),Data!$D$2:$D$32673 ))} -> #NUM! | D6: Data Scientist | E6: #NUM! | F6: =IF($D6<>title,E6,NA()) -> #NUM! | G6: =IF($D6=title,$E6,NA()) -> #N/A
A7: Senior Data Engineer | B7: {=MEDIAN( IF( (jobs[job_title_short]=A7)* (jobs[job_country]=country)* (ISNUMBER(SEARCH(type,jobs[job_schedule_type])))* (Data!$D$2:$D$32673<>0),Data!$D$2:$D$32673 ))} -> #NUM! | D7: Senior Data Engineer | E7: #NUM! | F7: =IF($D7<>title,E7,NA()) -> #NUM! | G7: =IF($D7=title,$E7,NA()) -> #N/A
A8: Data Analyst | B8: {=MEDIAN( IF( (jobs[job_title_short]=A8)* (jobs[job_country]=country)* (ISNUMBER(SEARCH(type,jobs[job_schedule_type])))* (Data!$D$2:$D$32673<>0),Data!$D$2:$D$32673 ))} -> #NUM! | D8: Data Analyst | E8: #NUM! | F8: =IF($D8<>title,E8,NA()) -> #NUM! | G8: =IF($D8=title,$E8,NA()) -> #N/A
A9: Software Engineer | B9: {=MEDIAN( IF( (jobs[job_title_short]=A9)* (jobs[job_country]=country)* (ISNUMBER(SEARCH(type,jobs[job_schedule_type])))* (Data!$D$2:$D$32673<>0),Data!$D$2:$D$32673 ))} -> #NUM! | D9: Software Engineer | E9: #NUM! | F9: =IF($D9<>title,E9,NA()) -> #NUM! | G9: =IF($D9=title,$E9,NA()) -> #N/A
A10: Business Analyst | B10: {=MEDIAN( IF( (jobs[job_title_short]=A10)* (jobs[job_country]=country)* (ISNUMBER(SEARCH(type,jobs[job_schedule_type])))* (Data!$D$2:$D$32673<>0),Data!$D$2:$D$32673 ))} -> #NUM! | D10: Business Analyst | E10: #NUM! | F10: =IF($D10<>title,E10,NA()) -> #NUM! | G10: =IF($D10=title,$E10,NA()) -> #N/A
A11: Cloud Engineer | B11: {=MEDIAN( IF( (jobs[job_title_short]=A11)* (jobs[job_country]=country)* (ISNUMBER(SEARCH(type,jobs[job_schedule_type])))* (Data!$D$2:$D$32673<>0),Data!$D$2:$D$32673 ))} -> #NUM! | D11: Cloud Engineer | E11: #NUM! | F11: =IF($D11<>title,E11,NA()) -> #NUM! | G11: =IF($D11=title,$E11,NA()) -> #N/A

Sheet Type
A1: {=_xlfn.UNIQUE(Data!B:B)} -> job_schedule_type | C1: Job_schedule_type | D1: Median_salary
A2: Full-time | C2: {=_xlfn._xlws.FILTER($A$2:$A$28, NOT(ISNUMBER(SEARCH("and",A2:A28)))*NOT(ISNUMBER(SEARCH("0",A2:A28))))} -> Full-time | D2: {=MEDIAN( IF( (jobs[job_country]=country)* (jobs[job_title_short]=title)* (ISNUMBER(SEARCH(C2,jobs[job_schedule_type])))* (Data!$D$2:$D$32673<>0),Data!$D$2:$D$32673))} -> 147500 | F2: {=_xlfn._xlws.SORT(_xlfn._xlws.FILTER(C2:D6,ISNUMBER(D2:D6)),2,1)} -> Contractor | G2: 45000 | H2: =IF($F2<>type,$G2,NA()) -> 45000 | I2: =IF($F2=type,$G2,NA()) -> #N/A
A3: Full-time and Part-time | C3: Contractor | D3: {=MEDIAN( IF( (jobs[job_country]=country)* (jobs[job_title_short]=title)* (ISNUMBER(SEARCH(C3,jobs[job_schedule_type])))* (Data!$D$2:$D$32673<>0),Data!$D$2:$D$32673))} -> 45000 | F3: Full-time | G3: 147500 | H3: =IF($F3<>type,$G3,NA()) -> 147500 | I3: =IF($F3=type,$G3,NA()) -> #N/A
A4: Contractor | C4: Part-time | D4: {=MEDIAN( IF( (jobs[job_country]=country)* (jobs[job_title_short]=title)* (ISNUMBER(SEARCH(C4,jobs[job_schedule_type])))* (Data!$D$2:$D$32673<>0),Data!$D$2:$D$32673))} -> #NUM! | H4: =IF($F4<>type,$G4,NA()) -> 0 | I4: =IF($F4=type,$G4,NA()) -> #N/A
A5: Full-time, Part-time, and Internship | C5: Internship | D5: {=MEDIAN( IF( (jobs[job_country]=country)* (jobs[job_title_short]=title)* (ISNUMBER(SEARCH(C5,jobs[job_schedule_type])))* (Data!$D$2:$D$32673<>0),Data!$D$2:$D$32673))} -> #NUM! | H5: =IF($F5<>type,$G5,NA()) -> 0 | I5: =IF($F5=type,$G5,NA()) -> #N/A
A6: Part-time | C6: Temp work | D6: {=MEDIAN( IF( (jobs[job_country]=country)* (jobs[job_title_short]=title)* (ISNUMBER(SEARCH(C6,jobs[job_schedule_type])))* (Data!$D$2:$D$32673<>0),Data!$D$2:$D$32673))} -> #NUM! | H6: =IF($F6<>type,$G6,NA()) -> 0 | I6: =IF($F6=type,$G6,NA()) -> #N/A
A7: Contractor and Temp work
A8: 0
A9: Full-time and Temp work
A10: Full-time and Contractor
A11: Full-time, Contractor, and Temp work
A12: Full-time, Part-time, and Temp work
A13: Full-time, Part-time, and Contractor
A14: Internship
A15: Full-time and Internship
A16: Part-time and Internship
A17: Full-time and Per diem
A18: Part-time and Contractor
A19: Temp work and Internship
A20: Temp work
... A28: Full-time, Part-time, and Volunteer

Sheet Country
A1: Country | B1: Median_salary
A2: {=_xlfn.ANCHORARRAY(Data_validation!F2)} -> Albania | B2: {=MEDIAN( IF( (jobs[job_title_short]=title)* (jobs[job_country]=A2)* (ISNUMBER(SEARCH(type,jobs[job_schedule_type])))* (jobs #REF! <>0), jobs #REF! ) )} -> #NAME?
A3: Algeria | B3: {=MEDIAN( IF( (jobs[job_title_short]=title)* (jobs[job_country]=A3)* (ISNUMBER(SEARCH(type,jobs[job_schedule_type])))* (jobs #REF! <>0), jobs #REF! ) )} -> #NAME?
A4: Argentina | B4: {=MEDIAN( IF( (jobs[job_title_short]=title)* (jobs[job_country]=A4)* (ISNUMBER(SEARCH(type,jobs[job_schedule_type])))* (jobs #REF! <>0), jobs #REF! ) )} -> #NAME?
A5: Armenia | B5: {=MEDIAN( IF( (jobs[job_title_short]=title)* (jobs[job_country]=A5)* (ISNUMBER(SEARCH(type,jobs[job_schedule_type])))* (jobs #REF! <>0), jobs #REF! ) )} -> #NAME?
A6: Australia | B6: {=MEDIAN( IF( (jobs[job_title_short]=title)* (jobs[job_country]=A6)* (ISNUMBER(SEARCH(type,jobs[job_schedule_type])))* (jobs #REF! <>0), jobs #REF! ) )} -> #NAME?
A7: Austria | B7: {=MEDIAN( IF( (jobs[job_title_short]=title)* (jobs[job_country]=A7)* (ISNUMBER(SEARCH(type,jobs[job_schedule_type])))* (jobs #REF! <>0), jobs #REF! ) )} -> #NAME?
A8: Azerbaijan | B8: {=MEDIAN( IF( (jobs[job_title_short]=title)* (jobs[job_country]=A8)* (ISNUMBER(SEARCH(type,jobs[job_schedule_type])))* (jobs #REF! <>0), jobs #REF! ) )} -> #NAME?
A9: Bahamas | B9: {=MEDIAN( IF( (jobs[job_title_short]=title)* (jobs[job_country]=A9)* (ISNUMBER(SEARCH(type,jobs[job_schedule_type])))* (jobs #REF! <>0), jobs #REF! ) )} -> #NAME?
A10: Bangladesh | B10: {=MEDIAN( IF( (jobs[job_title_short]=title)* (jobs[job_country]=A10)* (ISNUMBER(SEARCH(type,jobs[job_schedule_type])))* (jobs #REF! <>0), jobs #REF! ) )} -> #NAME?
A11: Belarus | B11: {=MEDIAN( IF( (jobs[job_title_short]=title)* (jobs[job_country]=A11)* (ISNUMBER(SEARCH(type,jobs[job_schedule_type])))* (jobs #REF! <>0), jobs #REF! ) )} -> #NAME?
A12: Belgium | B12: {=MEDIAN( IF( (jobs[job_title_short]=title)* (jobs[job_country]=A12)* (ISNUMBER(SEARCH(type,jobs[job_schedule_type])))* (jobs #REF! <>0), jobs #REF! ) )} -> #NAME?
A13: Benin | B13: {=MEDIAN( IF( (jobs[job_title_short]=title)* (jobs[job_country]=A13)* (ISNUMBER(SEARCH(type,jobs[job_schedule_type])))* (jobs #REF! <>0), jobs #REF! ) )} -> #NAME?
A14: Bolivia | B14: {=MEDIAN( IF( (jobs[job_title_short]=title)* (jobs[job_country]=A14)* (ISNUMBER(SEARCH(type,jobs[job_schedule_type])))* (jobs #REF! <>0), jobs #REF! ) )} -> #NAME?
... A112: Zimbabwe | B112: {=MEDIAN( IF( (jobs[job_title_short]=title)* (jobs[job_country]=A112)* (ISNUMBER(SEARCH(type,jobs[job_schedule_type])))* (jobs #REF! <>0), jobs #REF! ) )} -> #NAME?

Sheet Data_validation
A1: job_title_short | B1: count | C1: job_title_sorted | E1: job_counrty | F1: job_country_sorted
A2: {=_xlfn.UNIQUE(jobs[job_title_short])} -> Senior Data Scientist | B2: {=COUNT( IF( (jobs[job_country]=country)* (jobs[job_title_short]=A2)* (ISNUMBER(SEARCH(type,jobs[job_schedule_type]))), Data!$D$2:$D$32673) )} -> 0 | C2: {=_xlfn._xlws.SORT(A2:B11,2,-1)} -> Senior Data Scientist | D2: 0 | E2: {=_xlfn.UNIQUE(jobs[job_country])} -> Sudan | F2: {=_xlfn._xlws.SORT(_xlfn.ANCHORARRAY(E2))} -> Albania | G2: =_xlfn.XLOOKUP(title,$C$2:$C$11,$D$2:$D$11,"No results") -> 0
A3: Data Engineer | B3: {=COUNT( IF( (jobs[job_country]=country)* (jobs[job_title_short]=A3)* (ISNUMBER(SEARCH(type,jobs[job_schedule_type]))), Data!$D$2:$D$32673) )} -> 0 | C3: Data Engineer | D3: 0 | E3: United States | F3: Algeria
A4: Senior Data Analyst | B4: {=COUNT( IF( (jobs[job_country]=country)* (jobs[job_title_short]=A4)* (ISNUMBER(SEARCH(type,jobs[job_schedule_type]))), Data!$D$2:$D$32673) )} -> 0 | C4: Senior Data Analyst | D4: 0 | E4: France | F4: Argentina
A5: Machine Learning Engineer | B5: {=COUNT( IF( (jobs[job_country]=country)* (jobs[job_title_short]=A5)* (ISNUMBER(SEARCH(type,jobs[job_schedule_type]))), Data!$D$2:$D$32673) )} -> 0 | C5: Machine Learning Engineer | D5: 0 | E5: Mexico | F5: Armenia
A6: Data Scientist | B6: {=COUNT( IF( (jobs[job_country]=country)* (jobs[job_title_short]=A6)* (ISNUMBER(SEARCH(type,jobs[job_schedule_type]))), Data!$D$2:$D$32673) )} -> 0 | C6: Data Scientist | D6: 0 | E6: Canada | F6: Australia
A7: Senior Data Engineer | B7: {=COUNT( IF( (jobs[job_country]=country)* (jobs[job_title_short]=A7)* (ISNUMBER(SEARCH(type,jobs[job_schedule_type]))), Data!$D$2:$D$32673) )} -> 0 | C7: Senior Data Engineer | D7: 0 | E7: Croatia | F7: Austria
A8: Data Analyst | B8: {=COUNT( IF( (jobs[job_country]=country)* (jobs[job_title_short]=A8)* (ISNUMBER(SEARCH(type,jobs[job_schedule_type]))), Data!$D$2:$D$32673) )} -> 0 | C8: Data Analyst | D8: 0 | E8: Germany | F8: Azerbaijan
A9: Software Engineer | B9: {=COUNT( IF( (jobs[job_country]=country)* (jobs[job_title_short]=A9)* (ISNUMBER(SEARCH(type,jobs[job_schedule_type]))), Data!$D$2:$D$32673) )} -> 0 | C9: Software Engineer | D9: 0 | E9: Spain | F9: Bahamas
A10: Business Analyst | B10: {=COUNT( IF( (jobs[job_country]=country)* (jobs[job_title_short]=A10)* (ISNUMBER(SEARCH(type,jobs[job_schedule_type]))), Data!$D$2:$D$32673) )} -> 0 | C10: Business Analyst | D10: 0 | E10: India | F10: Bangladesh
A11: Cloud Engineer | B11: {=COUNT( IF( (jobs[job_country]=country)* (jobs[job_title_short]=A11)* (ISNUMBER(SEARCH(type,jobs[job_schedule_type]))), Data!$D$2:$D$32673) )} -> 0 | C11: Cloud Engineer | D11: 0 | E11: Estonia | F11: Belarus
E12: Greece | F12: Belgium
E13: Brazil | F13: Benin
E14: Cyprus | F14: Bolivia
E15: Indonesia | F15: Bosnia and Herzegovina
E16: Jamaica | F16: Brazil
E17: Netherlands | F17: Brunei
E18: Hong Kong | F18: Bulgaria
E19: Finland | F19: Cambodia
E20: Portugal | F20: Cameroon
E21: United Kingdom | F21: Canada
E22: Australia | F22: Chile
E23: Philippines | F23: China
... E112: Uruguay | F112: Zimbabwe

Sheet Platform
A1: {=_xlfn.UNIQUE(jobs[job_via])} -> via ZipRecruiter | B1: {=COUNTIFS(jobs[job_via],A1,jobs[job_title_short],title,jobs[job_country],country,jobs[job_schedule_type],type)} -> 0
A2: via Indeed | B2: {=COUNTIFS(jobs[job_via],A2,jobs[job_title_short],title,jobs[job_country],country,jobs[job_schedule_type],type)} -> 0 | D2: {=_xlfn._xlws.SORT(A1:B593,2,-1)} -> via ZipRecruiter | E2: 0 | G2: =SUBSTITUTE(D2,"via","") -> ZipRecruiter
A3: via Ai-Jobs.net | B3: {=COUNTIFS(jobs[job_via],A3,jobs[job_title_short],title,jobs[job_country],country,jobs[job_schedule_type],type)} -> 0 | D3: via Indeed | E3: 0
A4: via Snagajob | B4: {=COUNTIFS(jobs[job_via],A4,jobs[job_title_short],title,jobs[job_country],country,jobs[job_schedule_type],type)} -> 0 | D4: via Ai-Jobs.net | E4: 0
A5: via LinkedIn | B5: {=COUNTIFS(jobs[job_via],A5,jobs[job_title_short],title,jobs[job_country],country,jobs[job_schedule_type],type)} -> 0 | D5: via Snagajob | E5: 0
A6: via Hitmarker | B6: {=COUNTIFS(jobs[job_via],A6,jobs[job_title_short],title,jobs[job_country],country,jobs[job_schedule_type],type)} -> 0 | D6: via LinkedIn | E6: 0
A7: via Ladders | B7: {=COUNTIFS(jobs[job_via],A7,jobs[job_title_short],title,jobs[job_country],country,jobs[job_schedule_type],type)} -> 0 | D7: via Hitmarker | E7: 0
A8: via Federal Government Jobs | B8: {=COUNTIFS(jobs[job_via],A8,jobs[job_title_short],title,jobs[job_country],country,jobs[job_schedule_type],type)} -> 0 | D8: via Ladders | E8: 0
A9: via SaluteMyJob | B9: {=COUNTIFS(jobs[job_via],A9,jobs[job_title_short],title,jobs[job_country],country,jobs[job_schedule_type],type)} -> 0 | D9: via Federal Government Jobs | E9: 0
A10: via JobAffairs4u.com | B10: {=COUNTIFS(jobs[job_via],A10,jobs[job_title_short],title,jobs[job_country],country,jobs[job_schedule_type],type)} -> 0 | D10: via SaluteMyJob | E10: 0
A11: via Las Vegas, NV - Geebo | B11: {=COUNTIFS(jobs[job_via],A11,jobs[job_title_short],title,jobs[job_country],country,jobs[job_schedule_type],type)} -> 0 | D11: via JobAffairs4u.com | E11: 0
A12: via Motion Recruitment | B12: {=COUNTIFS(jobs[job_via],A12,jobs[job_title_short],title,jobs[job_country],country,jobs[job_schedule_type],type)} -> 0 | D12: via Las Vegas, NV - Geebo | E12: 0
A13: via Dice | B13: {=COUNTIFS(jobs[job_via],A13,jobs[job_title_short],title,jobs[job_country],country,jobs[job_schedule_type],type)} -> 0 | D13: via Motion Recruitment | E13: 0
A14: via JobServe | B14: {=COUNTIFS(jobs[job_via],A14,jobs[job_title_short],title,jobs[job_country],country,jobs[job_schedule_type],type)} -> 0 | D14: via Dice | E14: 0
... A152: via Santa Clara, CA - Geebo | B152: {=COUNTIFS(jobs[job_via],A152,jobs[job_title_short],title,jobs[job_country],country,jobs[job_schedule_type],type)} -> 0 | D152: via Jobs In ICT | E152: 0
A153: 0 | B153: {=COUNTIFS(jobs[job_via],A153,jobs[job_title_short],title,jobs[job_country],country,jobs[job_schedule_type],type)} -> 0 | D153: via Santa Clara, CA - Geebo | E153: 0
A154: via GeekLink | B154: {=COUNTIFS(jobs[job_via],A154,jobs[job_title_short],title,jobs[job_country],country,jobs[job_schedule_type],type)} -> 0 | D154: 0 | E154: 0
A155: via Four States Jobs | B155: {=COUNTIFS(jobs[job_via],A155,jobs[job_title_short],title,jobs[job_country],country,jobs[job_schedule_type],type)} -> 0 | D155: via GeekLink | E155: 0
A156: via WJBF Jobs | B156: {=COUNTIFS(jobs[job_via],A156,jobs[job_title_short],title,jobs[job_country],country,jobs[job_schedule_type],type)} -> 0 | D156: via Four States Jobs | E156: 0
A157: via Saint Peters, MO - Geebo | B157: {=COUNTIFS(jobs[job_via],A157,jobs[job_title_short],title,jobs[job_country],country,jobs[job_schedule_type],type)} -> 0 | D157: via WJBF Jobs | E157: 0
A158: via Arlington, TX - Geebo | B158: {=COUNTIFS(jobs[job_via],A158,jobs[job_title_short],title,jobs[job_country],country,jobs[job_schedule_type],type)} -> 0 | D158: via Saint Peters, MO - Geebo | E158: 0
A159: via Welcome To The Jungle | B159: {=COUNTIFS(jobs[job_via],A159,jobs[job_title_short],title,jobs[job_country],country,jobs[job_schedule_type],type)} -> 0 | D159: via Arlington, TX - Geebo | E159: 0
A160: via Miami, FL - Geebo | B160: {=COUNTIFS(jobs[job_via],A160,jobs[job_title_short],title,jobs[job_country],country,jobs[job_schedule_type],type)} -> 0 | D160: via Welcome To The Jungle | E160: 0
A161: via WGN-TV Jobs | B161: {=COUNTIFS(jobs[job_via],A161,jobs[job_title_short],title,jobs[job_country],country,jobs[job_schedule_type],type)} -> 0 | D161: via Miami, FL - Geebo | E161: 0
A162: via PIX11 Jobs | B162: {=COUNTIFS(jobs[job_via],A162,jobs[job_title_short],title,jobs[job_country],country,jobs[job_schedule_type],type)} -> 0 | D162: via WGN-TV Jobs | E162: 0
A163: via Modis | B163: {=COUNTIFS(jobs[job_via],A163,jobs[job_title_short],title,jobs[job_country],country,jobs[job_schedule_type],type)} -> 0 | D163: via PIX11 Jobs | E163: 0
A164: via Rebound | B164: {=COUNTIFS(jobs[job_via],A164,jobs[job_title_short],title,jobs[job_country],country,jobs[job_schedule_type],type)} -> 0 | D164: via Modis | E164: 0
A165: via Work RN | B165: {=COUNTIFS(jobs[job_via],A165,jobs[job_title_short],title,jobs[job_country],country,jobs[job_schedule_type],type)} -> 0 | D165: via Rebound | E165: 0
A166: via Schertz, TX - Geebo | B166: {=COUNTIFS(jobs[job_via],A166,jobs[job_title_short],title,jobs[job_country],country,jobs[job_schedule_type],type)} -> 0 | D166: via Work RN | E166: 0
... A593: via Form Energy - Talentify | B593: {=COUNTIFS(jobs[job_via],A593,jobs[job_title_short],title,jobs[job_country],country,jobs[job_schedule_type],type)} -> 0 | D593: via Jobs.computer.org | E593: 0
D594: via Form Energy - Talentify | E594: 0

Sheet Salary_Dashboard
C1: Data science salary calculator
C3: Job Title | J3: Country | P3: Type
C4: Data Engineer | J4: Czechia | P4: Internship
